Workbook

Sheet Data
A1: ID | B1: X | C1: Y
A2: 1 | B2: 28 | C2: 1028
A3: 2 | B3: 18 | C3: 1363
A4: 3 | B4: 21 | C4: 1257
A5: 4 | B5: 20 | C5: 1009
A6: 5 | B6: 28 | C6: 1916
A7: 6 | B7: 19 | C7: 1664
A8: 7 | B8: 18 | C8: 861
A9: 8 | B9: 19 | C9: 1247
A10: 9 | B10: 21 | C10: 1834
A11: 10 | B11: 27 | C11: 854
A12: 11 | B12: 26 | C12: 1207
A13: 12 | B13: 29 | C13: 1916
... A101: 100 | B101: 52 | C101: 7769

Sheet Iteration_1
A1: ID | B1: X | C1: Y | D1: Dist C1 | E1: Dist C2 | F1: Dist C3 | G1: Cluster | H1: MinDist
A2: =Data!A2 -> 1 | B2: =Data!B2 -> 28 | C2: =Data!C2 -> 1028 | D2: =SQRT((B2-[1]Centroids!B2)^2+(C2-[1]Centroids!C2)^2) -> 472.00953 | E2: =SQRT((B2-[1]Centroids!B3)^2+(C2-[1]Centroids!C3)^2) -> 2472.0291 | F2: =SQRT((B2-[1]Centroids!B4)^2+(C2-[1]Centroids!C4)^2) -> 6972.0734 | G2: =MATCH(MIN(D2:F2),D2:F2,0) -> 1 | H2: =MIN(D2:F2) -> 472.00953
A3: =Data!A3 -> 2 | B3: =Data!B3 -> 18 | C3: =Data!C3 -> 1363 | D3: =SQRT((B3-[1]Centroids!B2)^2+(C3-[1]Centroids!C2)^2) -> 137.17872 | E3: =SQRT((B3-[1]Centroids!B3)^2+(C3-[1]Centroids!C3)^2) -> 2137.1132 | F3: =SQRT((B3-[1]Centroids!B4)^2+(C3-[1]Centroids!C4)^2) -> 6637.1329 | G3: =MATCH(MIN(D3:F3),D3:F3,0) -> 1 | H3: =MIN(D3:F3) -> 137.17872
A4: =Data!A4 -> 3 | B4: =Data!B4 -> 21 | C4: =Data!C4 -> 1257 | D4: =SQRT((B4-[1]Centroids!B2)^2+(C4-[1]Centroids!C2)^2) -> 243.03292 | E4: =SQRT((B4-[1]Centroids!B3)^2+(C4-[1]Centroids!C3)^2) -> 2243.0805 | F4: =SQRT((B4-[1]Centroids!B4)^2+(C4-[1]Centroids!C4)^2) -> 6743.1128 | G4: =MATCH(MIN(D4:F4),D4:F4,0) -> 1 | H4: =MIN(D4:F4) -> 243.03292
A5: =Data!A5 -> 4 | B5: =Data!B5 -> 20 | C5: =Data!C5 -> 1009 | D5: =SQRT((B5-[1]Centroids!B2)^2+(C5-[1]Centroids!C2)^2) -> 491.02546 | E5: =SQRT((B5-[1]Centroids!B3)^2+(C5-[1]Centroids!C3)^2) -> 2491.0803 | F5: =SQRT((B5-[1]Centroids!B4)^2+(C5-[1]Centroids!C4)^2) -> 6991.1144 | G5: =MATCH(MIN(D5:F5),D5:F5,0) -> 1 | H5: =MIN(D5:F5) -> 491.02546
A6: =Data!A6 -> 5 | B6: =Data!B6 -> 28 | C6: =Data!C6 -> 1916 | D6: =SQRT((B6-[1]Centroids!B2)^2+(C6-[1]Centroids!C2)^2) -> 416.01082 | E6: =SQRT((B6-[1]Centroids!B3)^2+(C6-[1]Centroids!C3)^2) -> 1584.0455 | F6: =SQRT((B6-[1]Centroids!B4)^2+(C6-[1]Centroids!C4)^2) -> 6084.0842 | G6: =MATCH(MIN(D6:F6),D6:F6,0) -> 1 | H6: =MIN(D6:F6) -> 416.01082
A7: =Data!A7 -> 6 | B7: =Data!B7 -> 19 | C7: =Data!C7 -> 1664 | D7: =SQRT((B7-[1]Centroids!B2)^2+(C7-[1]Centroids!C2)^2) -> 164.10972 | E7: =SQRT((B7-[1]Centroids!B3)^2+(C7-[1]Centroids!C3)^2) -> 1836.1201 | F7: =SQRT((B7-[1]Centroids!B4)^2+(C7-[1]Centroids!C4)^2) -> 6336.1327 | G7: =MATCH(MIN(D7:F7),D7:F7,0) -> 1 | H7: =MIN(D7:F7) -> 164.10972
A8: =Data!A8 -> 7 | B8: =Data!B8 -> 18 | C8: =Data!C8 -> 861 | D8: =SQRT((B8-[1]Centroids!B2)^2+(C8-[1]Centroids!C2)^2) -> 639.03834 | E8: =SQRT((B8-[1]Centroids!B3)^2+(C8-[1]Centroids!C3)^2) -> 2639.0917 | F8: =SQRT((B8-[1]Centroids!B4)^2+(C8-[1]Centroids!C4)^2) -> 7139.1235 | G8: =MATCH(MIN(D8:F8),D8:F8,0) -> 1 | H8: =MIN(D8:F8) -> 639.03834
A9: =Data!A9 -> 8 | B9: =Data!B9 -> 19 | C9: =Data!C9 -> 1247 | D9: =SQRT((B9-[1]Centroids!B2)^2+(C9-[1]Centroids!C2)^2) -> 253.07114 | E9: =SQRT((B9-[1]Centroids!B3)^2+(C9-[1]Centroids!C3)^2) -> 2253.0979 | F9: =SQRT((B9-[1]Centroids!B4)^2+(C9-[1]Centroids!C4)^2) -> 6753.1245 | G9: =MATCH(MIN(D9:F9),D9:F9,0) -> 1 | H9: =MIN(D9:F9) -> 253.07114
A10: =Data!A10 -> 9 | B10: =Data!B10 -> 21 | C10: =Data!C10 -> 1834 | D10: =SQRT((B10-[1]Centroids!B2)^2+(C10-[1]Centroids!C2)^2) -> 334.02395 | E10: =SQRT((B10-[1]Centroids!B3)^2+(C10-[1]Centroids!C3)^2) -> 1666.1083 | F10: =SQRT((B10-[1]Centroids!B4)^2+(C10-[1]Centroids!C4)^2) -> 6166.1233 | G10: =MATCH(MIN(D10:F10),D10:F10,0) -> 1 | H10: =MIN(D10:F10) -> 334.02395
A11: =Data!A11 -> 10 | B11: =Data!B11 -> 27 | C11: =Data!C11 -> 854 | D11: =SQRT((B11-[1]Centroids!B2)^2+(C11-[1]Centroids!C2)^2) -> 646.0031 | E11: =SQRT((B11-[1]Centroids!B3)^2+(C11-[1]Centroids!C3)^2) -> 2646.0319 | F11: =SQRT((B11-[1]Centroids!B4)^2+(C11-[1]Centroids!C4)^2) -> 7146.0762 | G11: =MATCH(MIN(D11:F11),D11:F11,0) -> 1 | H11: =MIN(D11:F11) -> 646.0031
A12: =Data!A12 -> 11 | B12: =Data!B12 -> 26 | C12: =Data!C12 -> 1207 | D12: =SQRT((B12-[1]Centroids!B2)^2+(C12-[1]Centroids!C2)^2) -> 293.00171 | E12: =SQRT((B12-[1]Centroids!B3)^2+(C12-[1]Centroids!C3)^2) -> 2293.0427 | F12: =SQRT((B12-[1]Centroids!B4)^2+(C12-[1]Centroids!C4)^2) -> 6793.0851 | G12: =MATCH(MIN(D12:F12),D12:F12,0) -> 1 | H12: =MIN(D12:F12) -> 293.00171
A13: =Data!A13 -> 12 | B13: =Data!B13 -> 29 | C13: =Data!C13 -> 1916 | D13: =SQRT((B13-[1]Centroids!B2)^2+(C13-[1]Centroids!C2)^2) -> 416.01923 | E13: =SQRT((B13-[1]Centroids!B3)^2+(C13-[1]Centroids!C3)^2) -> 1584.0382 | F13: =SQRT((B13-[1]Centroids!B4)^2+(C13-[1]Centroids!C4)^2) -> 6084.079 | G13: =MATCH(MIN(D13:F13),D13:F13,0) -> 1 | H13: =MIN(D13:F13) -> 416.01923
A14: =Data!A14 -> 13 | B14: =Data!B14 -> 24 | C14: =Data!C14 -> 1251 | D14: =SQRT((B14-[1]Centroids!B2)^2+(C14-[1]Centroids!C2)^2) -> 249.00201 | E14: =SQRT((B14-[1]Centroids!B3)^2+(C14-[1]Centroids!C3)^2) -> 2249.0569 | F14: =SQRT((B14-[1]Centroids!B4)^2+(C14-[1]Centroids!C4)^2) -> 6749.096 | G14: =MATCH(MIN(D14:F14),D14:F14,0) -> 1 | H14: =MIN(D14:F14) -> 249.00201
A15: =Data!A15 -> 14 | B15: =Data!B15 -> 25 | C15: =Data!C15 -> 1369 | D15: =SQRT((B15-[1]Centroids!B2)^2+(C15-[1]Centroids!C2)^2) -> 131 | E15: =SQRT((B15-[1]Centroids!B3)^2+(C15-[1]Centroids!C3)^2) -> 2131.0528 | F15: =SQRT((B15-[1]Centroids!B4)^2+(C15-[1]Centroids!C4)^2) -> 6631.0924 | G15: =MATCH(MIN(D15:F15),D15:F15,0) -> 1 | H15: =MIN(D15:F15) -> 131
A16: =Data!A16 -> 15 | B16: =Data!B16 -> 30 | C16: =Data!C16 -> 813 | D16: =SQRT((B16-[1]Centroids!B2)^2+(C16-[1]Centroids!C2)^2) -> 687.01819 | E16: =SQRT((B16-[1]Centroids!B3)^2+(C16-[1]Centroids!C3)^2) -> 2687.0186 | F16: =SQRT((B16-[1]Centroids!B4)^2+(C16-[1]Centroids!C4)^2) -> 7187.0626 | G16: =MATCH(MIN(D16:F16),D16:F16,0) -> 1 | H16: =MIN(D16:F16) -> 687.01819
A17: =Data!A17 -> 16 | B17: =Data!B17 -> 30 | C17: =Data!C17 -> 1126 | D17: =SQRT((B17-[1]Centroids!B2)^2+(C17-[1]Centroids!C2)^2) -> 374.03342 | E17: =SQRT((B17-[1]Centroids!B3)^2+(C17-[1]Centroids!C3)^2) -> 2374.0211 | F17: =SQRT((B17-[1]Centroids!B4)^2+(C17-[1]Centroids!C4)^2) -> 6874.0655 | G17: =MATCH(MIN(D17:F17),D17:F17,0) -> 1 | H17: =MIN(D17:F17) -> 374.03342
A18: =Data!A18 -> 17 | B18: =Data!B18 -> 29 | C18: =Data!C18 -> 1665 | D18: =SQRT((B18-[1]Centroids!B2)^2+(C18-[1]Centroids!C2)^2) -> 165.04848 | E18: =SQRT((B18-[1]Centroids!B3)^2+(C18-[1]Centroids!C3)^2) -> 1835.033 | F18: =SQRT((B18-[1]Centroids!B4)^2+(C18-[1]Centroids!C4)^2) -> 6335.0758 | G18: =MATCH(MIN(D18:F18),D18:F18,0) -> 1 | H18: =MIN(D18:F18) -> 165.04848
A19: =Data!A19 -> 18 | B19: =Data!B19 -> 23 | C19: =Data!C19 -> 1369 | D19: =SQRT((B19-[1]Centroids!B2)^2+(C19-[1]Centroids!C2)^2) -> 131.01527 | E19: =SQRT((B19-[1]Centroids!B3)^2+(C19-[1]Centroids!C3)^2) -> 2131.0678 | F19: =SQRT((B19-[1]Centroids!B4)^2+(C19-[1]Centroids!C4)^2) -> 6631.1032 | G19: =MATCH(MIN(D19:F19),D19:F19,0) -> 1 | H19: =MIN(D19:F19) -> 131.01527
A20: =Data!A20 -> 19 | B20: =Data!B20 -> 20 | C20: =Data!C20 -> 1240 | D20: =SQRT((B20-[1]Centroids!B2)^2+(C20-[1]Centroids!C2)^2) -> 260.04807 | E20: =SQRT((B20-[1]Centroids!B3)^2+(C20-[1]Centroids!C3)^2) -> 2260.0885 | F20: =SQRT((B20-[1]Centroids!B4)^2+(C20-[1]Centroids!C4)^2) -> 6760.1183 | G20: =MATCH(MIN(D20:F20),D20:F20,0) -> 1 | H20: =MIN(D20:F20) -> 260.04807
A21: =Data!A21 -> 20 | B21: =Data!B21 -> 30 | C21: =Data!C21 -> 1489 | D21: =SQRT((B21-[1]Centroids!B2)^2+(C21-[1]Centroids!C2)^2) -> 12.083046 | E21: =SQRT((B21-[1]Centroids!B3)^2+(C21-[1]Centroids!C3)^2) -> 2011.0249 | F21: =SQRT((B21-[1]Centroids!B4)^2+(C21-[1]Centroids!C4)^2) -> 6511.0691 | G21: =MATCH(MIN(D21:F21),D21:F21,0) -> 1 | H21: =MIN(D21:F21) -> 12.083046
A22: =Data!A22 -> 21 | B22: =Data!B22 -> 19 | C22: =Data!C22 -> 989 | D22: =SQRT((B22-[1]Centroids!B2)^2+(C22-[1]Centroids!C2)^2) -> 511.03522 | E22: =SQRT((B22-[1]Centroids!B3)^2+(C22-[1]Centroids!C3)^2) -> 2511.0878 | F22: =SQRT((B22-[1]Centroids!B4)^2+(C22-[1]Centroids!C4)^2) -> 7011.1199 | G22: =MATCH(MIN(D22:F22),D22:F22,0) -> 1 | H22: =MIN(D22:F22) -> 511.03522
A23: =Data!A23 -> 22 | B23: =Data!B23 -> 24 | C23: =Data!C23 -> 998 | D23: =SQRT((B23-[1]Centroids!B2)^2+(C23-[1]Centroids!C2)^2) -> 502.001 | E23: =SQRT((B23-[1]Centroids!B3)^2+(C23-[1]Centroids!C3)^2) -> 2502.0512 | F23: =SQRT((B23-[1]Centroids!B4)^2+(C23-[1]Centroids!C4)^2) -> 7002.0925 | G23: =MATCH(MIN(D23:F23),D23:F23,0) -> 1 | H23: =MIN(D23:F23) -> 502.001
A24: =Data!A24 -> 23 | B24: =Data!B24 -> 23 | C24: =Data!C24 -> 1504 | D24: =SQRT((B24-[1]Centroids!B2)^2+(C24-[1]Centroids!C2)^2) -> 4.472136 | E24: =SQRT((B24-[1]Centroids!B3)^2+(C24-[1]Centroids!C3)^2) -> 1996.0724 | F24: =SQRT((B24-[1]Centroids!B4)^2+(C24-[1]Centroids!C4)^2) -> 6496.1054 | G24: =MATCH(MIN(D24:F24),D24:F24,0) -> 1 | H24: =MIN(D24:F24) -> 4.472136
A25: =Data!A25 -> 24 | B25: =Data!B25 -> 27 | C25: =Data!C25 -> 1341 | D25: =SQRT((B25-[1]Centroids!B2)^2+(C25-[1]Centroids!C2)^2) -> 159.01258 | E25: =SQRT((B25-[1]Centroids!B3)^2+(C25-[1]Centroids!C3)^2) -> 2159.0391 | F25: =SQRT((B25-[1]Centroids!B4)^2+(C25-[1]Centroids!C4)^2) -> 6659.0818 | G25: =MATCH(MIN(D25:F25),D25:F25,0) -> 1 | H25: =MIN(D25:F25) -> 159.01258
A26: =Data!A26 -> 25 | B26: =Data!B26 -> 30 | C26: =Data!C26 -> 888 | D26: =SQRT((B26-[1]Centroids!B2)^2+(C26-[1]Centroids!C2)^2) -> 612.02042 | E26: =SQRT((B26-[1]Centroids!B3)^2+(C26-[1]Centroids!C3)^2) -> 2612.0191 | F26: =SQRT((B26-[1]Centroids!B4)^2+(C26-[1]Centroids!C4)^2) -> 7112.0633 | G26: =MATCH(MIN(D26:F26),D26:F26,0) -> 1 | H26: =MIN(D26:F26) -> 612.02042
A27: =Data!A27 -> 26 | B27: =Data!B27 -> 29 | C27: =Data!C27 -> 1740 | D27: =SQRT((B27-[1]Centroids!B2)^2+(C27-[1]Centroids!C2)^2) -> 240.03333 | E27: =SQRT((B27-[1]Centroids!B3)^2+(C27-[1]Centroids!C3)^2) -> 1760.0344 | F27: =SQRT((B27-[1]Centroids!B4)^2+(C27-[1]Centroids!C4)^2) -> 6260.0768 | G27: =MATCH(MIN(D27:F27),D27:F27,0) -> 1 | H27: =MIN(D27:F27) -> 240.03333
A28: =Data!A28 -> 27 | B28: =Data!B28 -> 26 | C28: =Data!C28 -> 1055 | D28: =SQRT((B28-[1]Centroids!B2)^2+(C28-[1]Centroids!C2)^2) -> 445.00112 | E28: =SQRT((B28-[1]Centroids!B3)^2+(C28-[1]Centroids!C3)^2) -> 2445.0401 | F28: =SQRT((B28-[1]Centroids!B4)^2+(C28-[1]Centroids!C4)^2) -> 6945.0832 | G28: =MATCH(MIN(D28:F28),D28:F28,0) -> 1 | H28: =MIN(D28:F28) -> 445.00112
A29: =Data!A29 -> 28 | B29: =Data!B29 -> 24 | C29: =Data!C29 -> 961 | D29: =SQRT((B29-[1]Centroids!B2)^2+(C29-[1]Centroids!C2)^2) -> 539.00093 | E29: =SQRT((B29-[1]Centroids!B3)^2+(C29-[1]Centroids!C3)^2) -> 2539.0504 | F29: =SQRT((B29-[1]Centroids!B4)^2+(C29-[1]Centroids!C4)^2) -> 7039.0921 | G29: =MATCH(MIN(D29:F29),D29:F29,0) -> 1 | H29: =MIN(D29:F29) -> 539.00093
A30: =Data!A30 -> 29 | B30: =Data!B30 -> 26 | C30: =Data!C30 -> 1400 | D30: =SQRT((B30-[1]Centroids!B2)^2+(C30-[1]Centroids!C2)^2) -> 100.005 | E30: =SQRT((B30-[1]Centroids!B3)^2+(C30-[1]Centroids!C3)^2) -> 2100.0467 | F30: =SQRT((B30-[1]Centroids!B4)^2+(C30-[1]Centroids!C4)^2) -> 6600.0876 | G30: =MATCH(MIN(D30:F30),D30:F30,0) -> 1 | H30: =MIN(D30:F30) -> 100.005
A31: =Data!A31 -> 30 | B31: =Data!B31 -> 28 | C31: =Data!C31 -> 1540 | D31: =SQRT((B31-[1]Centroids!B2)^2+(C31-[1]Centroids!C2)^2) -> 40.112342 | E31: =SQRT((B31-[1]Centroids!B3)^2+(C31-[1]Centroids!C3)^2) -> 1960.0367 | F31: =SQRT((B31-[1]Centroids!B4)^2+(C31-[1]Centroids!C4)^2) -> 6460.0793 | G31: =MATCH(MIN(D31:F31),D31:F31,0) -> 1 | H31: =MIN(D31:F31) -> 40.112342
A32: =Data!A32 -> 31 | B32: =Data!B32 -> 27 | C32: =Data!C32 -> 1193 | D32: =SQRT((B32-[1]Centroids!B2)^2+(C32-[1]Centroids!C2)^2) -> 307.00651 | E32: =SQRT((B32-[1]Centroids!B3)^2+(C32-[1]Centroids!C3)^2) -> 2307.0366 | F32: =SQRT((B32-[1]Centroids!B4)^2+(C32-[1]Centroids!C4)^2) -> 6807.08 | G32: =MATCH(MIN(D32:F32),D32:F32,0) -> 1 | H32: =MIN(D32:F32) -> 307.00651
A33: =Data!A33 -> 32 | B33: =Data!B33 -> 29 | C33: =Data!C33 -> 942 | D33: =SQRT((B33-[1]Centroids!B2)^2+(C33-[1]Centroids!C2)^2) -> 558.01434 | E33: =SQRT((B33-[1]Centroids!B3)^2+(C33-[1]Centroids!C3)^2) -> 2558.0237 | F33: =SQRT((B33-[1]Centroids!B4)^2+(C33-[1]Centroids!C4)^2) -> 7058.0681 | G33: =MATCH(MIN(D33:F33),D33:F33,0) -> 1 | H33: =MIN(D33:F33) -> 558.01434
A34: =Data!A34 -> 33 | B34: =Data!B34 -> 18 | C34: =Data!C34 -> 1266 | D34: =SQRT((B34-[1]Centroids!B2)^2+(C34-[1]Centroids!C2)^2) -> 234.10468 | E34: =SQRT((B34-[1]Centroids!B3)^2+(C34-[1]Centroids!C3)^2) -> 2234.1083 | F34: =SQRT((B34-[1]Centroids!B4)^2+(C34-[1]Centroids!C4)^2) -> 6734.131 | G34: =MATCH(MIN(D34:F34),D34:F34,0) -> 1 | H34: =MIN(D34:F34) -> 234.10468
A35: =Data!A35 -> 34 | B35: =Data!B35 -> 39 | C35: =Data!C35 -> 2326 | D35: =SQRT((B35-[1]Centroids!B2)^2+(C35-[1]Centroids!C2)^2) -> 826.11864 | E35: =SQRT((B35-[1]Centroids!B3)^2+(C35-[1]Centroids!C3)^2) -> 1174.0004 | F35: =SQRT((B35-[1]Centroids!B4)^2+(C35-[1]Centroids!C4)^2) -> 5674.0389 | G35: =MATCH(MIN(D35:F35),D35:F35,0) -> 1 | H35: =MIN(D35:F35) -> 826.11864
A36: =Data!A36 -> 35 | B36: =Data!B36 -> 37 | C36: =Data!C36 -> 2413 | D36: =SQRT((B36-[1]Centroids!B2)^2+(C36-[1]Centroids!C2)^2) -> 913.07886 | E36: =SQRT((B36-[1]Centroids!B3)^2+(C36-[1]Centroids!C3)^2) -> 1087.0041 | F36: =SQRT((B36-[1]Centroids!B4)^2+(C36-[1]Centroids!C4)^2) -> 5587.0473 | G36: =MATCH(MIN(D36:F36),D36:F36,0) -> 1 | H36: =MIN(D36:F36) -> 913.07886
A37: =Data!A37 -> 36 | B37: =Data!B37 -> 42 | C37: =Data!C37 -> 3138 | D37: =SQRT((B37-[1]Centroids!B2)^2+(C37-[1]Centroids!C2)^2) -> 1638.0882 | E37: =SQRT((B37-[1]Centroids!B3)^2+(C37-[1]Centroids!C3)^2) -> 362.00552 | F37: =SQRT((B37-[1]Centroids!B4)^2+(C37-[1]Centroids!C4)^2) -> 4862.0333 | G37: =MATCH(MIN(D37:F37),D37:F37,0) -> 2 | H37: =MIN(D37:F37) -> 362.00552
A38: =Data!A38 -> 37 | B38: =Data!B38 -> 44 | C38: =Data!C38 -> 4603 | D38: =SQRT((B38-[1]Centroids!B2)^2+(C38-[1]Centroids!C2)^2) -> 3103.0582 | E38: =SQRT((B38-[1]Centroids!B3)^2+(C38-[1]Centroids!C3)^2) -> 1103.0073 | F38: =SQRT((B38-[1]Centroids!B4)^2+(C38-[1]Centroids!C4)^2) -> 3397.0377 | G38: =MATCH(MIN(D38:F38),D38:F38,0) -> 2 | H38: =MIN(D38:F38) -> 1103.0073
A39: =Data!A39 -> 38 | B39: =Data!B39 -> 41 | C39: =Data!C39 -> 2666 | D39: =SQRT((B39-[1]Centroids!B2)^2+(C39-[1]Centroids!C2)^2) -> 1166.1098 | E39: =SQRT((B39-[1]Centroids!B3)^2+(C39-[1]Centroids!C3)^2) -> 834.0006 | F39: =SQRT((B39-[1]Centroids!B4)^2+(C39-[1]Centroids!C4)^2) -> 5334.0338 | G39: =MATCH(MIN(D39:F39),D39:F39,0) -> 2 | H39: =MIN(D39:F39) -> 834.0006
A40: =Data!A40 -> 39 | B40: =Data!B40 -> 41 | C40: =Data!C40 -> 3455 | D40: =SQRT((B40-[1]Centroids!B2)^2+(C40-[1]Centroids!C2)^2) -> 1955.0655 | E40: =SQRT((B40-[1]Centroids!B3)^2+(C40-[1]Centroids!C3)^2) -> 45.01111 | F40: =SQRT((B40-[1]Centroids!B4)^2+(C40-[1]Centroids!C4)^2) -> 4545.0397 | G40: =MATCH(MIN(D40:F40),D40:F40,0) -> 2 | H40: =MIN(D40:F40) -> 45.01111
...

Sheet Iteration_2
A1: ID | B1: X | C1: Y | D1: Dist C1 | E1: Dist C2 | F1: Dist C3 | G1: Cluster | H1: MinDist
A2: =Data!A2 -> 1 | B2: =Data!B2 -> 28 | C2: =Data!C2 -> 1028 | D2: =SQRT((B2-Centroids!$D$2)^2+(C2-Centroids!$E$2)^2) -> 454.39041 | E2: =SQRT((B2-Centroids!$D$3)^2+(C2-Centroids!$E$3)^2) -> 2909.8369 | F2: =SQRT((B2-Centroids!$D$4)^2+(C2-Centroids!$E$4)^2) -> 6828.5644 | G2: =IF(D2=MIN(D2:F2),1,IF(E2=MIN(D2:F2),2,3)) -> 1 | H2: =MIN(D2:F2) -> 454.39041
A3: =Data!A3 -> 2 | B3: =Data!B3 -> 18 | C3: =Data!C3 -> 1363 | D3: =SQRT((B3-Centroids!$D$2)^2+(C3-Centroids!$E$2)^2) -> 119.77637 | E3: =SQRT((B3-Centroids!$D$3)^2+(C3-Centroids!$E$3)^2) -> 2574.924 | F3: =SQRT((B3-Centroids!$D$4)^2+(C3-Centroids!$E$4)^2) -> 6493.6212 | G3: =IF(D3=MIN(D3:F3),1,IF(E3=MIN(D3:F3),2,3)) -> 1 | H3: =MIN(D3:F3) -> 119.77637
A4: =Data!A4 -> 3 | B4: =Data!B4 -> 21 | C4: =Data!C4 -> 1257 | D4: =SQRT((B4-Centroids!$D$2)^2+(C4-Centroids!$E$2)^2) -> 225.48714 | E4: =SQRT((B4-Centroids!$D$3)^2+(C4-Centroids!$E$3)^2) -> 2680.8915 | F4: =SQRT((B4-Centroids!$D$4)^2+(C4-Centroids!$E$4)^2) -> 6599.6019 | G4: =IF(D4=MIN(D4:F4),1,IF(E4=MIN(D4:F4),2,3)) -> 1 | H4: =MIN(D4:F4) -> 225.48714
A5: =Data!A5 -> 4 | B5: =Data!B5 -> 20 | C5: =Data!C5 -> 1009 | D5: =SQRT((B5-Centroids!$D$2)^2+(C5-Centroids!$E$2)^2) -> 473.4514 | E5: =SQRT((B5-Centroids!$D$3)^2+(C5-Centroids!$E$3)^2) -> 2928.8912 | F5: =SQRT((B5-Centroids!$D$4)^2+(C5-Centroids!$E$4)^2) -> 6847.6036 | G5: =IF(D5=MIN(D5:F5),1,IF(E5=MIN(D5:F5),2,3)) -> 1 | H5: =MIN(D5:F5) -> 473.4514
A6: =Data!A6 -> 5 | B6: =Data!B6 -> 28 | C6: =Data!C6 -> 1916 | D6: =SQRT((B6-Centroids!$D$2)^2+(C6-Centroids!$E$2)^2) -> 433.60993 | E6: =SQRT((B6-Centroids!$D$3)^2+(C6-Centroids!$E$3)^2) -> 2021.8561 | F6: =SQRT((B6-Centroids!$D$4)^2+(C6-Centroids!$E$4)^2) -> 5940.5741 | G6: =IF(D6=MIN(D6:F6),1,IF(E6=MIN(D6:F6),2,3)) -> 1 | H6: =MIN(D6:F6) -> 433.60993
A7: =Data!A7 -> 6 | B7: =Data!B7 -> 19 | C7: =Data!C7 -> 1664 | D7: =SQRT((B7-Centroids!$D$2)^2+(C7-Centroids!$E$2)^2) -> 181.81373 | E7: =SQRT((B7-Centroids!$D$3)^2+(C7-Centroids!$E$3)^2) -> 2273.9302 | F7: =SQRT((B7-Centroids!$D$4)^2+(C7-Centroids!$E$4)^2) -> 6192.6207 | G7: =IF(D7=MIN(D7:F7),1,IF(E7=MIN(D7:F7),2,3)) -> 1 | H7: =MIN(D7:F7) -> 181.81373
A8: =Data!A8 -> 7 | B8: =Data!B8 -> 18 | C8: =Data!C8 -> 861 | D8: =SQRT((B8-Centroids!$D$2)^2+(C8-Centroids!$E$2)^2) -> 621.46455 | E8: =SQRT((B8-Centroids!$D$3)^2+(C8-Centroids!$E$3)^2) -> 3076.9027 | F8: =SQRT((B8-Centroids!$D$4)^2+(C8-Centroids!$E$4)^2) -> 6995.6125 | G8: =IF(D8=MIN(D8:F8),1,IF(E8=MIN(D8:F8),2,3)) -> 1 | H8: =MIN(D8:F8) -> 621.46455
A9: =Data!A9 -> 8 | B9: =Data!B9 -> 19 | C9: =Data!C9 -> 1247 | D9: =SQRT((B9-Centroids!$D$2)^2+(C9-Centroids!$E$2)^2) -> 235.54765 | E9: =SQRT((B9-Centroids!$D$3)^2+(C9-Centroids!$E$3)^2) -> 2690.9089 | F9: =SQRT((B9-Centroids!$D$4)^2+(C9-Centroids!$E$4)^2) -> 6609.6131 | G9: =IF(D9=MIN(D9:F9),1,IF(E9=MIN(D9:F9),2,3)) -> 1 | H9: =MIN(D9:F9) -> 235.54765
A10: =Data!A10 -> 9 | B10: =Data!B10 -> 21 | C10: =Data!C10 -> 1834 | D10: =SQRT((B10-Centroids!$D$2)^2+(C10-Centroids!$E$2)^2) -> 351.67188 | E10: =SQRT((B10-Centroids!$D$3)^2+(C10-Centroids!$E$3)^2) -> 2103.9184 | F10: =SQRT((B10-Centroids!$D$4)^2+(C10-Centroids!$E$4)^2) -> 6022.6116 | G10: =IF(D10=MIN(D10:F10),1,IF(E10=MIN(D10:F10),2,3)) -> 1 | H10: =MIN(D10:F10) -> 351.67188
A11: =Data!A11 -> 10 | B11: =Data!B11 -> 27 | C11: =Data!C11 -> 854 | D11: =SQRT((B11-Centroids!$D$2)^2+(C11-Centroids!$E$2)^2) -> 628.39054 | E11: =SQRT((B11-Centroids!$D$3)^2+(C11-Centroids!$E$3)^2) -> 3083.8398 | F11: =SQRT((B11-Centroids!$D$4)^2+(C11-Centroids!$E$4)^2) -> 7002.5672 | G11: =IF(D11=MIN(D11:F11),1,IF(E11=MIN(D11:F11),2,3)) -> 1 | H11: =MIN(D11:F11) -> 628.39054
A12: =Data!A12 -> 11 | B12: =Data!B12 -> 26 | C12: =Data!C12 -> 1207 | D12: =SQRT((B12-Centroids!$D$2)^2+(C12-Centroids!$E$2)^2) -> 275.39495 | E12: =SQRT((B12-Centroids!$D$3)^2+(C12-Centroids!$E$3)^2) -> 2730.8522 | F12: =SQRT((B12-Centroids!$D$4)^2+(C12-Centroids!$E$4)^2) -> 6649.5754 | G12: =IF(D12=MIN(D12:F12),1,IF(E12=MIN(D12:F12),2,3)) -> 1 | H12: =MIN(D12:F12) -> 275.39495
A13: =Data!A13 -> 12 | B13: =Data!B13 -> 29 | C13: =Data!C13 -> 1916 | D13: =SQRT((B13-Centroids!$D$2)^2+(C13-Centroids!$E$2)^2) -> 433.61198 | E13: =SQRT((B13-Centroids!$D$3)^2+(C13-Centroids!$E$3)^2) -> 2021.8485 | F13: =SQRT((B13-Centroids!$D$4)^2+(C13-Centroids!$E$4)^2) -> 5940.5692 | G13: =IF(D13=MIN(D13:F13),1,IF(E13=MIN(D13:F13),2,3)) -> 1 | H13: =MIN(D13:F13) -> 433.61198
... A101: =Data!A101 -> 100 | B101: =Data!B101 -> 52 | C101: =Data!C101 -> 7769 | D101: =SQRT((B101-Centroids!$D$2)^2+(C101-Centroids!$E$2)^2) -> 6286.6571 | E101: =SQRT((B101-Centroids!$D$3)^2+(C101-Centroids!$E$3)^2) -> 3831.2153 | F101: =SQRT((B101-Centroids!$D$4)^2+(C101-Centroids!$E$4)^2) -> 87.6833 | G101: =IF(D101=MIN(D101:F101),1,IF(E101=MIN(D101:F101),2,3)) -> 3 | H101: =MIN(D101:F101) -> 87.6833

Sheet Iteration_3
A1: ID | B1: X | C1: Y | D1: Dist C1 | E1: Dist C2 | F1: Dist C3 | G1: Cluster | H1: MinDist
A2: =Data!A2 -> 1 | B2: =Data!B2 -> 28 | C2: =Data!C2 -> 1028 | D2: =SQRT((B2-Centroids!$F$2)^2+(C2-Centroids!$G$2)^2) -> 555.75601 | E2: =SQRT((B2-Centroids!$F$3)^2+(C2-Centroids!$G$3)^2) -> 3120.2442 | F2: =SQRT((B2-Centroids!$F$4)^2+(C2-Centroids!$G$4)^2) -> 6828.5644 | G2: =IF(D2=MIN(D2:F2),1,IF(E2=MIN(D2:F2),2,3)) -> 1 | H2: =MIN(D2:F2) -> 555.75601
A3: =Data!A3 -> 2 | B3: =Data!B3 -> 18 | C3: =Data!C3 -> 1363 | D3: =SQRT((B3-Centroids!$F$2)^2+(C3-Centroids!$G$2)^2) -> 221.01526 | E3: =SQRT((B3-Centroids!$F$3)^2+(C3-Centroids!$G$3)^2) -> 2785.327 | F3: =SQRT((B3-Centroids!$F$4)^2+(C3-Centroids!$G$4)^2) -> 6493.6212 | G3: =IF(D3=MIN(D3:F3),1,IF(E3=MIN(D3:F3),2,3)) -> 1 | H3: =MIN(D3:F3) -> 221.01526
A4: =Data!A4 -> 3 | B4: =Data!B4 -> 21 | C4: =Data!C4 -> 1257 | D4: =SQRT((B4-Centroids!$F$2)^2+(C4-Centroids!$G$2)^2) -> 326.84653 | E4: =SQRT((B4-Centroids!$F$3)^2+(C4-Centroids!$G$3)^2) -> 2891.2963 | F4: =SQRT((B4-Centroids!$F$4)^2+(C4-Centroids!$G$4)^2) -> 6599.6019 | G4: =IF(D4=MIN(D4:F4),1,IF(E4=MIN(D4:F4),2,3)) -> 1 | H4: =MIN(D4:F4) -> 326.84653
A5: =Data!A5 -> 4 | B5: =Data!B5 -> 20 | C5: =Data!C5 -> 1009 | D5: =SQRT((B5-Centroids!$F$2)^2+(C5-Centroids!$G$2)^2) -> 574.82157 | E5: =SQRT((B5-Centroids!$F$3)^2+(C5-Centroids!$G$3)^2) -> 3139.2964 | F5: =SQRT((B5-Centroids!$F$4)^2+(C5-Centroids!$G$4)^2) -> 6847.6036 | G5: =IF(D5=MIN(D5:F5),1,IF(E5=MIN(D5:F5),2,3)) -> 1 | H5: =MIN(D5:F5) -> 574.82157
A6: =Data!A6 -> 5 | B6: =Data!B6 -> 28 | C6: =Data!C6 -> 1916 | D6: =SQRT((B6-Centroids!$F$2)^2+(C6-Centroids!$G$2)^2) -> 332.24521 | E6: =SQRT((B6-Centroids!$F$3)^2+(C6-Centroids!$G$3)^2) -> 2232.2617 | F6: =SQRT((B6-Centroids!$F$4)^2+(C6-Centroids!$G$4)^2) -> 5940.5741 | G6: =IF(D6=MIN(D6:F6),1,IF(E6=MIN(D6:F6),2,3)) -> 1 | H6: =MIN(D6:F6) -> 332.24521
A7: =Data!A7 -> 6 | B7: =Data!B7 -> 19 | C7: =Data!C7 -> 1664 | D7: =SQRT((B7-Centroids!$F$2)^2+(C7-Centroids!$G$2)^2) -> 80.829924 | E7: =SQRT((B7-Centroids!$F$3)^2+(C7-Centroids!$G$3)^2) -> 2484.3319 | F7: =SQRT((B7-Centroids!$F$4)^2+(C7-Centroids!$G$4)^2) -> 6192.6207 | G7: =IF(D7=MIN(D7:F7),1,IF(E7=MIN(D7:F7),2,3)) -> 1 | H7: =MIN(D7:F7) -> 80.829924
A8: =Data!A8 -> 7 | B8: =Data!B8 -> 18 | C8: =Data!C8 -> 861 | D8: =SQRT((B8-Centroids!$F$2)^2+(C8-Centroids!$G$2)^2) -> 722.83492 | E8: =SQRT((B8-Centroids!$F$3)^2+(C8-Centroids!$G$3)^2) -> 3287.3076 | F8: =SQRT((B8-Centroids!$F$4)^2+(C8-Centroids!$G$4)^2) -> 6995.6125 | G8: =IF(D8=MIN(D8:F8),1,IF(E8=MIN(D8:F8),2,3)) -> 1 | H8: =MIN(D8:F8) -> 722.83492
A9: =Data!A9 -> 8 | B9: =Data!B9 -> 19 | C9: =Data!C9 -> 1247 | D9: =SQRT((B9-Centroids!$F$2)^2+(C9-Centroids!$G$2)^2) -> 336.89555 | E9: =SQRT((B9-Centroids!$F$3)^2+(C9-Centroids!$G$3)^2) -> 2901.3129 | F9: =SQRT((B9-Centroids!$F$4)^2+(C9-Centroids!$G$4)^2) -> 6609.6131 | G9: =IF(D9=MIN(D9:F9),1,IF(E9=MIN(D9:F9),2,3)) -> 1 | H9: =MIN(D9:F9) -> 336.89555
A10: =Data!A10 -> 9 | B10: =Data!B10 -> 21 | C10: =Data!C10 -> 1834 | D10: =SQRT((B10-Centroids!$F$2)^2+(C10-Centroids!$G$2)^2) -> 250.36322 | E10: =SQRT((B10-Centroids!$F$3)^2+(C10-Centroids!$G$3)^2) -> 2314.3203 | F10: =SQRT((B10-Centroids!$F$4)^2+(C10-Centroids!$G$4)^2) -> 6022.6116 | G10: =IF(D10=MIN(D10:F10),1,IF(E10=MIN(D10:F10),2,3)) -> 1 | H10: =MIN(D10:F10) -> 250.36322
A11: =Data!A11 -> 10 | B11: =Data!B11 -> 27 | C11: =Data!C11 -> 854 | D11: =SQRT((B11-Centroids!$F$2)^2+(C11-Centroids!$G$2)^2) -> 729.75756 | E11: =SQRT((B11-Centroids!$F$3)^2+(C11-Centroids!$G$3)^2) -> 3294.247 | F11: =SQRT((B11-Centroids!$F$4)^2+(C11-Centroids!$G$4)^2) -> 7002.5672 | G11: =IF(D11=MIN(D11:F11),1,IF(E11=MIN(D11:F11),2,3)) -> 1 | H11: =MIN(D11:F11) -> 729.75756
A12: =Data!A12 -> 11 | B12: =Data!B12 -> 26 | C12: =Data!C12 -> 1207 | D12: =SQRT((B12-Centroids!$F$2)^2+(C12-Centroids!$G$2)^2) -> 376.76531 | E12: =SQRT((B12-Centroids!$F$3)^2+(C12-Centroids!$G$3)^2) -> 2941.2588 | F12: =SQRT((B12-Centroids!$F$4)^2+(C12-Centroids!$G$4)^2) -> 6649.5754 | G12: =IF(D12=MIN(D12:F12),1,IF(E12=MIN(D12:F12),2,3)) -> 1 | H12: =MIN(D12:F12) -> 376.76531
A13: =Data!A13 -> 12 | B13: =Data!B13 -> 29 | C13: =Data!C13 -> 1916 | D13: =SQRT((B13-Centroids!$F$2)^2+(C13-Centroids!$G$2)^2) -> 332.24457 | E13: =SQRT((B13-Centroids!$F$3)^2+(C13-Centroids!$G$3)^2) -> 2232.2545 | F13: =SQRT((B13-Centroids!$F$4)^2+(C13-Centroids!$G$4)^2) -> 5940.5692 | G13: =IF(D13=MIN(D13:F13),1,IF(E13=MIN(D13:F13),2,3)) -> 1 | H13: =MIN(D13:F13) -> 332.24457
... A101: =Data!A101 -> 100 | B101: =Data!B101 -> 52 | C101: =Data!C101 -> 7769 | D101: =SQRT((B101-Centroids!$F$2)^2+(C101-Centroids!$G$2)^2) -> 6185.2883 | E101: =SQRT((B101-Centroids!$F$3)^2+(C101-Centroids!$G$3)^2) -> 3620.8076 | F101: =SQRT((B101-Centroids!$F$4)^2+(C101-Centroids!$G$4)^2) -> 87.6833 | G101: =IF(D101=MIN(D101:F101),1,IF(E101=MIN(D101:F101),2,3)) -> 3 | H101: =MIN(D101:F101) -> 87.6833

Sheet Centroids
A1: Cluster | B1: Iter1_X | C1: Iter1_Y | D1: Iter2_X | E1: Iter2_Y | F1: Iter3_X | G1: Iter3_Y
A2: 1 | B2: 25 | C2: 1500 | D2: =AVERAGEIF(Iteration_1!G:G,1,Iteration_1!B:B) -> 27.609756 | E2: =AVERAGEIF(Iteration_1!G:G,1,Iteration_1!C:C) -> 1482.3902 | F2: =AVERAGEIF(Iteration_2!G:G,1,Iteration_2!B:B) -> 28.711111 | G2: =AVERAGEIF(Iteration_2!G:G,1,Iteration_2!C:C) -> 1583.7556
A3: 2 | B3: 40 | C3: 3500 | D3: =AVERAGEIF(Iteration_1!G:G,2,Iteration_1!B:B) -> 43.965517 | E3: =AVERAGEIF(Iteration_1!G:G,2,Iteration_1!C:C) -> 3937.7931 | F3: =AVERAGEIF(Iteration_2!G:G,2,Iteration_2!B:B) -> 44.6 | G3: =AVERAGEIF(Iteration_2!G:G,2,Iteration_2!C:C) -> 4148.2
A4: 3 | B4: 60 | C4: 8000 | D4: =AVERAGEIF(Iteration_1!G:G,3,Iteration_1!B:B) -> 57.666667 | E4: =AVERAGEIF(Iteration_1!G:G,3,Iteration_1!C:C) -> 7856.5 | F4: =AVERAGEIF(Iteration_2!G:G,3,Iteration_2!B:B) -> 57.666667 | G4: =AVERAGEIF(Iteration_2!G:G,3,Iteration_2!C:C) -> 7856.5

Sheet Variance
A1: Iteration | B1: Variance
A2: 1 | B2: =SUM(Iteration_1!H2:H101) -> 79394.778
A3: 2 | B3: =SUM(Iteration_2!H2:H101) -> 76366.887
A4: 3 | B4: =SUM(Iteration_3!H2:H101) -> 76063.648
